Workbook

Sheet 执行清单
A1: ID | B1: 模块 | C1: 需求（一句话） | D1: 类型 | E1: 优先级 | F1: 负责方 | G1: 状态 | H1: 预估工时(d) | I1: Sprint | J1: 依赖 | K1: 备注/来源
A2: E-01 | B2: Event | C2: 新增 status 字段（upcoming/ongoing/ended），由 start/end time 自动计算 | D2: LOGIC+DB | E2: P0 | F2: 后端 | G2: 未开始 | H2: 2 | I2: S1 | K2: 一次性解决 5 条 UI 反馈
A3: E-02 | B3: Event | C3: Event list API 支持 status/category/tag/date/cost/recurrence/sort 参数 | D3: API | E3: P0 | F3: 后端 | G3: 未开始 | H3: 3 | I3: S1 | J3: E-01 | K3: map/home/community 共用
A4: E-03 | B4: Event | C4: 新增 recurrence 字段（none/daily/weekly/monthly）+ filter 选项 | D4: DB+LOGIC | E4: P1 | F4: 后端 | G4: 未开始 | H4: 2 | I4: S1 | K4: UTMSU 早餐、Grace on demand
A5: E-04 | B5: Event | C5: Event 支持多 host（多对多关系） | D5: DB | E5: P1 | F5: 后端 | G5: 未开始 | H5: 1.5 | I5: S1 | K5: 前端参考 Meetup 显示 and 2 others
A6: E-05 | B6: Event | C6: 新增 cost 字段 + 对应 filter | D6: DB+API | E6: P1 | F6: 后端 | G6: 未开始 | H6: 0.5 | I6: S1 | K6: Harvey
A7: E-06 | B7: Event | C7: Category 修正：accessibility→service、iccit→academic | D7: DB | E7: P1 | F7: 后端 | G7: 未开始 | H7: 0.5 | I7: S1 | K7: Harvey
A8: E-07 | B8: Event | C8: Category 新增 Science（含 Bio） | D8: DB | E8: P2 | F8: 后端 | G8: 未开始 | H8: 0.3 | I8: S2 | K8: Julian
A9: E-08 | B9: Event | C9: Popularity 从 views 改为 click-through rate | D9: LOGIC | E9: P1 | F9: 后端 | G9: 未开始 | H9: 2 | I9: S2 | J9: A-01 | K9: Gurleen、Frank
A10: E-09 | B10: Event | C10: Registration link 有效性校验（录入时校验 URL） | D10: LOGIC | E10: P1 | F10: 后端 | G10: 未开始 | H10: 1 | I10: S2 | K10: MCSS valentine polaroids 等点不动
A11: E-10 | B11: Event | C11: 数据清洗：去掉 2030 等异常日期 event | D11: LOGIC | E11: P2 | F11: 后端 | G11: 未开始 | H11: 0.5 | I11: S2 | K11: Gurshan
A12: E-11 | B12: Event | C12: event list 返回 total_count 字段 | D12: API | E12: P2 | F12: 后端 | G12: 未开始 | H12: 0.3 | I12: S2 | J12: E-02 | K12: Frank
A13: E-12 | B13: Event | C13: 海报原图 URL 字段（支持点击放大） | D13: DB | E13: P2 | F13: 后端 | G13: 未开始 | H13: 0.3 | I13: S2 | K13: Melody
A14: E-13 | B14: Event | C14: past event 分段查询（7d/1m/2m） | D14: API | E14: P3 | F14: 后端 | G14: 未开始 | H14: 0.5 | I14: S3 | J14: E-02 | K14: Frank
A15: M-01 | B15: Map | C15: Building 表建模：name/aliases/image/coords/description | D15: DB | E15: P0 | F15: 后端 | G15: 未开始 | H15: 1.5 | I15: S1 | K15: 支撑搜索 + hover
A16: M-02 | B16: Map | C16: GET /buildings/{id}/events 按时间范围返回 event list | D16: API | E16: P0 | F16: 后端 | G16: 未开始 | H16: 1 | I16: S1 | J16: M-01,E-02
A17: M-03 | B17: Map | C17: Map 默认时间范围：当前日期 ±30 天 | D17: LOGIC | E17: P1 | F17: 后端 | G17: 未开始 | H17: 0.3 | I17: S1 | J17: E-02 | K17: Gurleen
A18: M-04 | B18: Map | C18: Map 不展示 ended events（filter 默认） | D18: LOGIC | E18: P1 | F18: 前端+后端 | G18: 未开始 | H18: 0.3 | I18: S1 | J18: E-01 | K18: Frank
A19: M-05 | B19: Map | C19: 首页 mini map 每建筑活动数量 count 字段 | D19: API | E19: P2 | F19: 后端 | G19: 未开始 | H19: 0.5 | I19: S2 | J19: M-02 | K19: mobile 版
A20: M-06 | B20: Map | C20: 新增 MapPOI 表（prayer room/washroom/food/residence desk） | D20: DB+API | E20: P2 | F20: 后端 | G20: 未开始 | H20: 2 | I20: S3 | K20: Kaylee，长期价值高
A21: C-01 | B21: Community | C21: Club 表建模：含 avatar/category(max 3)/ig/linktree/follower_count | D21: DB | E21: P0 | F21: 后端 | G21: 未开始 | H21: 1 | I21: S1
A22: C-02 | B22: Community | C22: Club 和 Event 多对多关联 | D22: DB | E22: P1 | F22: 后端 | G22: 未开始 | H22: 0.5 | I22: S1 | J22: C-01
A23: C-03 | B23: Community | C23: Category 枚举统一（18 个 tag，社团+活动共用） | D23: DB | E23: P1 | F23: 前端+后端 | G23: 未开始 | H23: 0.5 | I23: S1 | K23: 见文档 tag 表
A24: C-04 | B24: Community | C24: 列表排序：只保留 Most followers + Alphabetical | D24: API | E24: P1 | F24: 后端 | G24: 未开始 | H24: 0.3 | I24: S1 | K24: Noah
A25: C-05 | B25: Community | C25: 社团卡片的 event_count 只算 ongoing | D25: API | E25: P2 | F25: 后端 | G25: 未开始 | H25: 0.3 | I25: S2 | J25: E-01 | K25: Melody
A26: C-06 | B26: Community | C26: Related Clubs 计算（基于 category / 共同活动） | D26: LOGIC+API | E26: P2 | F26: 后端 | G26: 未开始 | H26: 1.5 | I26: S3 | J26: C-01,C-03 | K26: Kauri
A27: C-07 | B27: Community | C27: Trending Clubs 数据源加上 services | D27: DB+API | E27: P2 | F27: 后端 | G27: 未开始 | H27: 0.3 | I27: S2 | K27: Harvey
A28: S-01 | B28: Search | C28: 建筑/社团 alias 词库（DH/MN/RAWC 等） | D28: DB+LOGIC | E28: P0 | F28: 后端 | G28: 未开始 | H28: 1.5 | I28: S1 | J28: M-01,C-01 | K28: 成本低影响大
A29: S-02 | B29: Search | C29: Home/Map/Community 用同一个搜索接口 | D29: API | E29: P1 | F29: 后端 | G29: 未开始 | H29: 1 | I29: S1 | J29: S-01
A30: S-03 | B30: Search | C30: 多语言搜索支持（长期） | D30: LOGIC | E30: P3 | F30: 后端 | G30: 未开始 | H30: 5 | I30: 待定 | K30: Gurleen，国际学生
A31: U-01 | B31: User/Auth | C31: Google OAuth 登录 | D31: AUTH | E31: P1 | F31: 后端 | G31: 未开始 | H31: 2 | I31: S2 | K31: Frank
A32: U-02 | B32: User/Auth | C32: 角色区分：general/club_exec(verified)/admin + 权限控制 | D32: AUTH | E32: P0 | F32: 后端 | G32: 未开始 | H32: 3 | I32: S2 | J32: U-01 | K32: 决定能不能 post event
A33: U-03 | B33: User/Auth | C33: POST /events：verified 直发，普通走审核队列 | D33: API+LOGIC | E33: P1 | F33: 后端 | G33: 未开始 | H33: 2 | I33: S2 | J33: U-02 | K33: Frank
A34: U-04 | B34: User/Auth | C34: User profile 增加 saved_events（原 favourite） | D34: DB+API | E34: P1 | F34: 后端 | G34: 未开始 | H34: 1 | I34: S2 | K34: Jelani、Kauri
A35: U-05 | B35: User/Auth | C35: User profile 增加 recently_viewed_events | D35: DB+API | E35: P1 | F35: 后端 | G35: 未开始 | H35: 1 | I35: S2 | K35: Jelani、Kauri
A36: A-01 | B36: Analytics | C36: 埋点：bounce rate / time on page / CTR / demand | D36: DB+LOGIC | E36: P1 | F36: 后端 | G36: 未开始 | H36: 3 | I36: S2 | K36: Nabil，可接 GA/PostHog
A37: A-02 | B37: Analytics | C37: Popularity 计算作业（基于 CTR 定时跑） | D37: LOGIC | E37: P2 | F37: 后端 | G37: 未开始 | H37: 1.5 | I37: S3 | J37: A-01
A38: N-01 | B38: Content | C38: 接入 CLNX 作为活动数据源 | D38: CRAWLER | E38: P0 | F38: 后端 | G38: 未开始 | H38: 4 | I38: S1 | K38: Harvey
A39: N-02 | B39: Content | C39: 增加 ICCIT 过往活动数据覆盖 | D39: CRAWLER | E39: P1 | F39: 后端 | G39: 未开始 | H39: 2 | I39: S2 | K39: Jelani
A40: N-03 | B40: Content | C40: 接入 Admissions open house / campus tour（utmfuture） | D40: CRAWLER | E40: P1 | F40: 后端 | G40: 未开始 | H40: 3 | I40: S2 | J40: E-03 | K40: Harvey
...

Sheet 统计
A1: What2Do 需求统计仪表盘
A3: 按优先级 | D3: Sprint 1 总工时(d) | E3: =SUMIF(执行清单!I:I,"S1",执行清单!H:H) -> 21.9
A4: 优先级 | B4: 数量 | C4: 占比 | D4: Sprint 2 总工时(d) | E4: =SUMIF(执行清单!I:I,"S2",执行清单!H:H) -> 27.3
A5: P0 | B5: =COUNTIF(执行清单!E:E,"P0") -> 8 | C5: =B5/SUM($B$5:$B$8) -> 0.18181818 | D5: Sprint 3 总工时(d) | E5: =SUMIF(执行清单!I:I,"S3",执行清单!H:H) -> 5.5
A6: P1 | B6: =COUNTIF(执行清单!E:E,"P1") -> 23 | C6: =B6/SUM($B$5:$B$8) -> 0.52272727 | D6: 总需求条数 | E6: =COUNTA(执行清单!A:A)-1 -> 44
A7: P2 | B7: =COUNTIF(执行清单!E:E,"P2") -> 11 | C7: =B7/SUM($B$5:$B$8) -> 0.25 | D7: 总工时估算(d) | E7: =SUM(执行清单!H:H) -> 59.7
A8: P3 | B8: =COUNTIF(执行清单!E:E,"P3") -> 2 | C8: =B8/SUM($B$5:$B$8) -> 0.045454545
A10: 按模块
A11: 模块 | B11: 数量
A12: Event | B12: =COUNTIF(执行清单!B:B,"Event") -> 13
A13: Map | B13: =COUNTIF(执行清单!B:B,"Map") -> 6
A14: Community | B14: =COUNTIF(执行清单!B:B,"Community") -> 7
A15: Search | B15: =COUNTIF(执行清单!B:B,"Search") -> 3
A16: User/Auth | B16: =COUNTIF(执行清单!B:B,"User/Auth") -> 5
A17: Analytics | B17: =COUNTIF(执行清单!B:B,"Analytics") -> 2
A18: Content | B18: =COUNTIF(执行清单!B:B,"Content") -> 5
A19: Feedback | B19: =COUNTIF(执行清单!B:B,"Feedback") -> 3
A22: 按状态
A23: 状态 | B23: 数量
A24: 未开始 | B24: =COUNTIF(执行清单!G:G,"未开始") -> 44
A25: 进行中 | B25: =COUNTIF(执行清单!G:G,"进行中") -> 0
A26: 待验收 | B26: =COUNTIF(执行清单!G:G,"待验收") -> 0
A27: 已完成 | B27: =COUNTIF(执行清单!G:G,"已完成") -> 0
A28: 暂缓 | B28: =COUNTIF(执行清单!G:G,"暂缓") -> 0

Sheet 会议纪要模板
A1: 需求评审会议纪要 [日期]
A3: 时间
A4: 参与人
A5: 会议目标
A7: 本次 Sprint 范围
B8: 从执行清单勾选出本 Sprint 做的 ID：
A14: 关键决策
B15: 1.
B16: 2.
B17: 3.
A19: 遗留问题 / 下次讨论
B20: -
B21: -
A23: Action Items
B24: 谁 | 做什么 | DDL
B25: | |
B26: | |
A28: 下次同步时间
